<?xml version="1.0"?>
<robot xmlns:xacro="http://ros.org/wiki/xacro">
  <xacro:include filename="geometry.xacro" />
  <xacro:include filename="macros.xacro" />

  <xacro:irb_120_link
    name="gripper_base"
    orig_xyz="${orig_gripper_base}"
    orig_rpy="${orig_gripper_base_rpy}"
    parent="link6"
    joint_type="fixed"
    joint_xyz="${orig_link6_joint}"
  />

  <link name="gripper_finger1">
    <contact>
      <lateral_friction value="1"/>
      <spinning_friction value="1"/>
    </contact>
    <collision>
      <geometry>
        <box size="0.0025 0.005 0.025" />
      </geometry>
      <origin rpy="1.5707963267948966 0 1.5707963267948966" xyz="0.0445 -0.0025 0"/>
    </collision>
    <visual>
      <geometry>
          <mesh filename="../cad/gripper_finger.dae" scale="1"/>
      </geometry>
      <origin rpy="1.5707963267948966 0 1.5707963267948966" xyz="0 0 0"/>
    </visual>
  </link>

  <joint name="joint_gripper_base_gripper_finger1" type="prismatic">
    <axis xyz="0 -1 0"/>
    <limit effort="1000.0" lower="0" upper="0.012" velocity="0.5"/>
    <origin rpy="0 0 0" xyz="0 0 0"/>
    <parent link="gripper_base"/>
    <child link="gripper_finger1"/>
    <dynamics damping="0" friction="0" spring_reference="0" spring_stiffness="0" />
  </joint>

  <link name="gripper_finger2">
    <contact>
      <lateral_friction value="1"/>
      <spinning_friction value="1"/>
    </contact>
    <collision>
      <geometry>
        <box size="0.0025 0.005 0.025" />
      </geometry>
      <origin rpy="-1.5707963267948966 0 -1.5707963267948966" xyz="0.0445 0.0025 0"/>
    </collision>
    <visual>
      <geometry>
          <mesh filename="../cad/gripper_finger.dae" scale="1"/>
      </geometry>
      <origin rpy="-1.5707963267948966 0 -1.5707963267948966" xyz="0 0 0"/>
    </visual>
  </link>

  <joint name="joint_gripper_base_gripper_finger2" type="prismatic">
    <axis xyz="0 1 0"/>
    <limit effort="1000.0" lower="0" upper="0.012" velocity="0.5"/>
    <origin rpy="0 0 0" xyz="0 0 0"/>
    <parent link="gripper_base"/>
    <child link="gripper_finger2"/>
    <dynamics damping="0" friction="0" spring_reference="0" spring_stiffness="0" />
  </joint>
</robot>